Workbook

Sheet Unified_Spec
A1: AUTOMETRIC — UNIFIED BRAND × CAMPAIGN MATCH SPEC
A2: One model that keeps Brand, Campaign, Content Style, and Creator/Brand Personality explicit. The original Brand Match engine remains intact; Unified Match adds Campaign Fit as a contextual layer.
A4: Layer | B4: What it answers | C4: Included signals | D4: Where
A5: BRAND | B5: Is this creator a fit for the brand itself? | C5: Industry, category, keywords, audience, content/category, brand personality, performance, safety | D5: Matching_Engine
A6: CAMPAIGN | B6: Is this creator suitable for this specific activation? | C6: Campaign objective, audience, content style, creator personality, communication style, platform | D6: Campaign_Profile + Campaign_Match
A7: CONTENT STYLE | B7: How should the creator make the content? | C7: Content Style Match + campaign Content Style | D7: Matching_Engine W + Campaign_Profile
A8: PERSONALITY | B8: Does creator personality fit brand/campaign personality? | C8: Brand Personality Fit, creator personality, tone, values, communication style | D8: Matching_Engine Y:AB + Campaign_Profile
A9: UNIFIED SCORE | B9: What is the final contextual fit for this campaign? | C9: 70% Brand Match + 30% Campaign Fit | D9: Unified_Match
A11: DEFAULT WEIGHTS | B11: Value | C11: Notes
A12: Base Brand Match | B12: 70% | C12: Preserves existing Brand Match score and its six component groups.
A13: Campaign Fit | B13: 30% | C13: Campaign-specific context; editable in Campaign_Match formula.
A14: Campaign Fit internals | B14: 30% Audience / 30% Style / 25% Personality / 15% Communication Style | C14: Objective remains a campaign descriptor and can later become a dedicated signal if backend data supports it.
A16: IMPORTANT | B16: Style and personality are NOT merged into generic category labels. Brand and campaign remain separate contexts, so the same creator can score differently across brands and campaigns.
A17: DATA NOTE
A18: VALIDATION TARGET

Sheet README
A1: AUTOMETRIC — KOL DISCOVERY BRAND MATCH ENGINE
A2: Specification and calculation workbook. Twelve sheets: two of inputs, one engine, seven views, one lookup sheet and this page. Generated by scripts/build-brand-match-workbook.mjs and verified by scripts/verify-brand-match-workbook.mjs.
A4: 1. PURPOSE
B5: This workbook is the source of truth for the Autometric KOL Discovery Brand Match calculation. It is not a mock-up: every score on every sheet is an Excel formula over the values in Brand_Profile and KOL_Database, weighted by the constants on Lookup_Lists. Change an input and the workbook re-answers. Hand it to a backend developer and the formulas are the specification — there is no second document that says what the code should do.
B6: It exists because the product needs a Brand Match today and the KOL database cannot supply one: feature.brand_fit_analysis holds 0 rows, which is why four of the eight Smart Preset chips in the running prototype are disabled. The logic has to be agreed and written down before the pipeline is built, not after.
A7: 2. BRAND_PROFILE — the brand half of the inputs
B8: Four sections, matching the Brand Profile & Matching UI: A. Company Profile, B. Target Audience, C. Brand Identification, D. Ideal Creator Profile. A fifth block, E. Matching Configuration, holds the switches that decide which rules act as hard filters.
B9: Columns D, E and F are the three brands. Column G is whichever brand cell B4 names, and that is the column the active-brand views (Match_Explanation, Discovery_Ranking) read. Two calculated blocks sit under the fields: a token helper that splits the comma-separated list fields into five addressable slots, and the audience sub-weights, which move weight onto whichever dimension Audience Demographics Priority names.
A10: 3. KOL_DATABASE — the creator half of the inputs
B11: Thirty creators on Instagram and TikTok, in six blocks: identity, performance, audience, content, commercial, safety — plus the exclusion state and the freshness columns Discovery needs. Tier, CPV, CPE, CPM, Estimated Reach, Estimated ROI, View-to-Follower Ratio, Cost Efficiency, Data Completeness and Data Status are calculated from the columns beside them.
B12: Several creators are missing a field on purpose — a blank Median Views, a blank rate card, a blank audience city. The real roster is full of holes, the Confidence column exists to report them, and every formula here is written to survive one without printing #DIV/0!.
A13: 4. THE SIX COMPONENTS
A14: Brand & Business Relevance | B14: Brand Industry, Product / Service Category, Main Business Keywords, Brand Keywords and Brand Niche against the creator Category, Sub Category, Content Topics and Audience Interests. Industry Match 40%, Category Match 30%, Keyword Match 30% — the last being the two keyword lists scored separately and averaged.
A15: Target Audience Relevance | B15: Age 25%, Gender 15%, Location 30%, Interest 30% — before Audience Demographics Priority moves 12 points onto one of them and takes a third of that off each of the others.
A16: Content & Category Relevance | B16: Preferred Category 30%, Preferred Sub Category 20%, Preferred Content Topics 30%, Preferred Content Style 20%.
A17: Brand Personality Fit | B17: Personality 35%, Tone against Content Style 25%, Values overlap 25%, Communication Style 15%. Related matches count: Innovative is answered by a Tech-savvy or Creative creator, not only by one who calls themselves Innovative.
A18: Performance Quality | B18: Engagement Rate 35%, Audience Quality 20%, Consistency 20%, Community 10%, Average Views 10%, Recent Growth 5%, each normalised to 0–100 against a calibration target on Lookup_Lists.
A19: Brand Safety | B19: Brand Safety Score 80%, head-room from Competitor Saturation 20%, multiplied by the Risk Flag discount (High 0.6, Medium 0.85, Low 0.95). Saturation lowers the score; it never excludes on its own.
A20: 5. WEIGHTING — the master formula
A21: FINAL MATCH = 20% Brand & Business + 30% Target Audience + 20% Content & Category + 10% Brand Personality + 10% Performance + 10% Brand Safety
B23: The six weights live in the COMPONENT WEIGHTS block on Lookup_Lists and nowhere else. The engine divides by their sum rather than by a literal 100, so a workbook whose weights have been edited still produces a 0–100 score; the CHECK_WEIGHT_TOTAL cell beside them says out loud whether they still total 100.
A24: 6. FORMULA LOGIC — how a comparison becomes a number
A25: Category-style comparisons | B25: A matrix lookup on Lookup_Lists, on the 100 / 80 / 60 / 40 / 20 ladder: exact, strongly related, partially related, weakly related, unrelated. Five matrices — Industry × Category, Category × Category, Brand Personality × Creator Personality, Brand Tone × Content Style, Communication Style × Content Style, Content Style × Content Style. Every cell is editable, which is what makes a disputed score a conversation about one number rather than about a model.
A26: List comparisons | B26: Overlap counting. The brand list is split into five slots by the token helper; each slot is looked for in the creator text with SEARCH; the score is matches ÷ slots filled × 100. A brand that names three keywords is judged out of three.
A27: Numeric comparisons | B27: Normalisation against a target on Lookup_Lists: MIN(100, value ÷ target × 100). Engagement Rate scores 100 at 6%; views per follower at 0.5; 30-day growth at 8%, and 0 at −2%.
A28: Missing data | B28: A blank input scores the neutral 50 where the brand left a preference blank, and 0 where the creator is missing a measurement — those are different situations and the formulas keep them apart. Nothing ever divides by an unguarded cell.
A29: Two inputs that carry no weight | B29: Company Description is free text for the brief. Brand Positioning is carried and printed in the Personality Match Reason, but it is deliberately not weighted: the honest thing to weigh a Premium or Luxury positioning against is production quality, and there is no measured production-quality signal on the roster to weigh it against. Inventing one would be the same mistake as the four Smart Preset chips that used to rank by a hash of the creator id. Give it a weight the day a real signal exists.
A30: 7. HARD FILTERS — remove the creator
B31: Platform, Minimum and Maximum Followers, Minimum Engagement Rate, Tier, Minimum Audience Quality, Minimum Brand Safety, Audience Country and Category (both switchable), Max Competitor Saturation, the four exclusion toggles, and Minimum Brand Match. The engine computes the reason first and the verdict from it, so an excluded creator always carries the sentence that explains why. See Filter_Logic.
A32: 8. SOFT MATCHING — reorder the list
B33: Brand Match, Audience Match, Content Relevance, Personality Fit, Performance, Opportunity, Estimated ROI and Competitor Saturation. A low soft score never removes a creator. Competitor Saturation in particular is a warning, not a rejection: it can only exclude through the explicit Max Competitor Saturation setting.
A34: 9. DISCOVERY RANKING
B35: Default order is Brand Match, then Audience Match, then Content Relevance, then Performance, then Brand Safety, encoded as one Default Sort Key so the tie-break order is inspectable. Thirty presets are defined on Lookup_Lists; the picker on Discovery_Ranking reads the metric column each one names. The "Available today" column tells you which of them the KOL database can actually answer — the prototype ships four of its eight chips disabled for exactly this reason.
A36: 10. MATCH EXPLANATION
B37: Generated, not written. The three strengths are the three highest components and the three considerations the three lowest, read with LARGE and SMALL over the same cells the score came from, so an explanation cannot drift away from the number it explains. Each component also carries its own reason line naming its sub-scores.
A38: 11. SAMPLE BRANDS AND SAMPLE OUTPUT
B39: Three briefs — Technology / SaaS, Beauty & Skincare, Food & Beverage — run against one roster of thirty. Sample_Output puts the three scores for each creator side by side and reports the spread. If the engine were ranking creators globally rather than matching brand to creator, that spread would be zero on every row; the verdict cell says whether it is.
A40: 12. TAXONOMY — the tree everything classifies against
B41: One sheet, because the whole point is that the four things are one object: a creator sub category, a brand niche, a raw kol_categories row and a matching keyword are four views of a single tree. Lookup_Lists derives its Category, Sub Category, Industry and Niche dropdowns from it, so no list in this workbook can drift from another.
A42: Three axes | B42: A label answers one question — what the creator makes, who watches, or how it is shot. public.kol_categories mixes all three: "Moms" is an audience and "Gen Z" is an age band, both sitting in a content column. Only the content axis may feed the Category and Sub Category ladders; the audience axis already has its own 30% of the score.
...

Sheet Brand_Profile
A1: BRAND PROFILE · Company Profile · Target Audience · Brand Identification · Ideal Creator Profile
A2: The inputs. Columns D–F are the three brands, each cell typed by hand or picked from a dropdown; column G is whichever brand cell B4 names, and that is the column the engine reads for every active-brand view. Nothing on this sheet is calculated from a creator — it is what the brand says about itself before it has seen the roster.
A4: Active Brand → | B4: BRAND-A | G4: active column → | H4: =MATCH($B$4,$D$6:$F$6,0) -> 1
A6: Section | B6: Field | C6: Field Key | D6: BRAND-A | E6: BRAND-B | F6: BRAND-C | G6: Active Value | H6: Input type / allowed values
A7: A. COMPANY PROFILE
A8: COMPANY PROFILE | B8: Brand ID | C8: brand_id | D8: BRAND-A | E8: BRAND-B | F8: BRAND-C | G8: =INDEX($D8:$F8,1,$H$4) -> BRAND-A | H8: Free text
A9: COMPANY PROFILE | B9: Brand Name | C9: brand_name | D9: Nusatech Cloud | E9: Lumaya Skin | F9: Rasa Nusantara | G9: =INDEX($D9:$F9,1,$H$4) -> Nusatech Cloud | H9: Free text
A10: COMPANY PROFILE | B10: Industry | C10: industry | D10: Technology / SaaS | E10: Beauty & Skincare | F10: Food & Beverage | G10: =INDEX($D10:$F10,1,$H$4) -> Technology / SaaS | H10: Dropdown — Lookup_Lists.Industry
A11: COMPANY PROFILE | B11: Company Description | C11: company_description | D11: Workflow automation and team collaboration for Indonesian SMEs. | E11: Dermatologist-tested skincare for humid-climate skin barriers. | F11: Ready-to-drink archipelago flavours for everyday family tables. | G11: =INDEX($D11:$F11,1,$H$4) -> Workflow automation and team collaboration for Indonesian SMEs. | H11: Free text
A12: COMPANY PROFILE | B12: Product / Service Category | C12: product_category | D12: Software & SaaS | E12: Skincare | F12: Coffee & Beverage | G12: =INDEX($D12:$F12,1,$H$4) -> Software & SaaS | H12: Dropdown — Lookup_Lists.SubCategory
A13: COMPANY PROFILE | B13: Main Business Keywords | C13: business_keywords | D13: Technology, Productivity, Business, Education, Finance | E13: Skincare, Beauty, Makeup, Health, Shopping | F13: Food, Cooking, Coffee, Shopping, Entertainment | G13: =INDEX($D13:$F13,1,$H$4) -> Technology, Productivity, Business, Education, Finance | H13: Up to 5 items, comma-separated
A14: COMPANY PROFILE | B14: Brand Niche | C14: brand_niche | D14: B2B SaaS | E14: Derma Skincare | F14: Ready-to-Drink | G14: =INDEX($D14:$F14,1,$H$4) -> B2B SaaS | H14: Dropdown — Lookup_Lists.Niche
A15: B. TARGET AUDIENCE
A16: TARGET AUDIENCE | B16: Primary Age Range | C16: primary_age_range | D16: 25-34 | E16: 18-24 | F16: 25-34 | G16: =INDEX($D16:$F16,1,$H$4) -> 25-34 | H16: Dropdown — Lookup_Lists.AgeBand
A17: TARGET AUDIENCE | B17: Secondary Age Range | C17: secondary_age_range | D17: 18-24 | E17: 25-34 | F17: 35-44 | G17: =INDEX($D17:$F17,1,$H$4) -> 18-24 | H17: Dropdown — Lookup_Lists.AgeBand
A18: TARGET AUDIENCE | B18: Gender Majority | C18: gender_majority | D18: Any | E18: Female | F18: Balanced | G18: =INDEX($D18:$F18,1,$H$4) -> Any | H18: Dropdown — Lookup_Lists.GenderMajority
A19: TARGET AUDIENCE | B19: Target Country | C19: target_country | D19: Indonesia | E19: Indonesia | F19: Indonesia | G19: =INDEX($D19:$F19,1,$H$4) -> Indonesia | H19: Dropdown — Lookup_Lists.Country
A20: TARGET AUDIENCE | B20: Target Region / Province | C20: target_region | D20: DKI Jakarta | E20: Nasional | F20: Nasional | G20: =INDEX($D20:$F20,1,$H$4) -> DKI Jakarta | H20: Dropdown — Lookup_Lists.Region
A21: TARGET AUDIENCE | B21: Target City | C21: target_city | D21: Jakarta | E21: Jakarta | F21: Nasional | G21: =INDEX($D21:$F21,1,$H$4) -> Jakarta | H21: Dropdown — Lookup_Lists.City
A22: TARGET AUDIENCE | B22: Audience Interests | C22: audience_interests | D22: Technology, Business, Productivity, Education, Finance | E22: Skincare, Beauty, Makeup, Fashion, Shopping | F22: Food, Cooking, Coffee, Travel, Entertainment | G22: =INDEX($D22:$F22,1,$H$4) -> Technology, Business, Productivity, Education, Finance | H22: Up to 5 items, comma-separated
A23: TARGET AUDIENCE | B23: Audience Demographics Priority | C23: audience_priority | D23: Interest | E23: Gender | F23: Age | G23: =INDEX($D23:$F23,1,$H$4) -> Interest | H23: Dropdown — Lookup_Lists.AudiencePriority
A24: C. BRAND IDENTIFICATION
A25: BRAND IDENTIFICATION | B25: Brand Personality | C25: brand_personality | D25: Innovative | E25: Premium | F25: Friendly | G25: =INDEX($D25:$F25,1,$H$4) -> Innovative | H25: Dropdown — Lookup_Lists.BrandPersonality
A26: BRAND IDENTIFICATION | B26: Brand Values | C26: brand_values | D26: Innovation, Trust, Transparency, Quality, Empowerment | E26: Quality, Authenticity, Trust, Craftsmanship, Health | F26: Fun, Community, Affordability, Authenticity, Family | G26: =INDEX($D26:$F26,1,$H$4) -> Innovation, Trust, Transparency, Quality, Empowerment | H26: Up to 5 items, comma-separated
A27: BRAND IDENTIFICATION | B27: Brand Tone | C27: brand_tone | D27: Informative | E27: Aspirational | F27: Warm | G27: =INDEX($D27:$F27,1,$H$4) -> Informative | H27: Dropdown — Lookup_Lists.BrandTone
A28: BRAND IDENTIFICATION | B28: Brand Positioning | C28: brand_positioning | D28: Mid-market | E28: Premium | F28: Mass | G28: =INDEX($D28:$F28,1,$H$4) -> Mid-market | H28: Dropdown — Lookup_Lists.Positioning
A29: BRAND IDENTIFICATION | B29: Brand Keywords | C29: brand_keywords | D29: Technology, Productivity, Business, Education, Finance | E29: Skincare, Beauty, Health, Makeup, Shopping | F29: Food, Cooking, Coffee, Entertainment, Shopping | G29: =INDEX($D29:$F29,1,$H$4) -> Technology, Productivity, Business, Education, Finance | H29: Up to 5 items, comma-separated
A30: BRAND IDENTIFICATION | B30: Communication Style | C30: communication_style | D30: Educational | E30: Visual-first | F30: Storytelling | G30: =INDEX($D30:$F30,1,$H$4) -> Educational | H30: Dropdown — Lookup_Lists.CommStyle
A31: D. IDEAL CREATOR PROFILE
A32: IDEAL CREATOR PROFILE | B32: Preferred Platform | C32: preferred_platform | D32: Instagram, TikTok | E32: Instagram, TikTok | F32: Instagram, TikTok | G32: =INDEX($D32:$F32,1,$H$4) -> Instagram, TikTok | H32: One or more of the Platform list, comma-separated
A33: IDEAL CREATOR PROFILE | B33: Preferred Category | C33: preferred_category | D33: Tech | E33: Beauty | F33: Food | G33: =INDEX($D33:$F33,1,$H$4) -> Tech | H33: Dropdown — Lookup_Lists.Category
A34: IDEAL CREATOR PROFILE | B34: Preferred Sub Category | C34: preferred_subcategory | D34: Software & SaaS | E34: Skincare | F34: Culinary Review | G34: =INDEX($D34:$F34,1,$H$4) -> Software & SaaS | H34: Dropdown — Lookup_Lists.SubCategory
A35: IDEAL CREATOR PROFILE | B35: Preferred Tier | C35: preferred_tier | D35: Micro, Mid-tier, Macro | E35: Micro, Mid-tier | F35: Nano, Micro, Mid-tier | G35: =INDEX($D35:$F35,1,$H$4) -> Micro, Mid-tier, Macro | H35: One or more of the Tier list, comma-separated
A36: IDEAL CREATOR PROFILE | B36: Preferred Follower Range — Min | C36: preferred_followers_min | D36: 10000 | E36: 10000 | F36: 5000 | G36: =INDEX($D36:$F36,1,$H$4) -> 10000 | H36: Whole number
A37: IDEAL CREATOR PROFILE | B37: Preferred Follower Range — Max | C37: preferred_followers_max | D37: 1000000 | E37: 500000 | F37: 400000 | G37: =INDEX($D37:$F37,1,$H$4) -> 1000000 | H37: Whole number
A38: IDEAL CREATOR PROFILE | B38: Minimum Engagement Rate (%) | C38: min_engagement_rate | D38: 2.5 | E38: 3 | F38: 3.5 | G38: =INDEX($D38:$F38,1,$H$4) -> 2.5 | H38: Percent, e.g. 3.5 means 3,5%
A39: IDEAL CREATOR PROFILE | B39: Preferred Content Style | C39: preferred_content_style | D39: Educational | E39: Review | F39: Storytelling | G39: =INDEX($D39:$F39,1,$H$4) -> Educational | H39: Dropdown — Lookup_Lists.ContentStyle
A40: IDEAL CREATOR PROFILE | B40: Preferred Content Topics | C40: preferred_content_topics | D40: Technology, Business, Education, Productivity, Finance | E40: Skincare, Beauty, Makeup, Health, Shopping | F40: Food, Cooking, Coffee, Entertainment, Travel | G40: =INDEX($D40:$F40,1,$H$4) -> Technology, Business, Education, Productivity, Finance | H40: Up to 5 items, comma-separated
A41: IDEAL CREATOR PROFILE | B41: Preferred Creator Personality | C41: preferred_creator_personality | D41: Educational | E41: Reviewer | F41: Relatable | G41: =INDEX($D41:$F41,1,$H$4) -> Educational | H41: Dropdown — Lookup_Lists.CreatorPersonality
A42: IDEAL CREATOR PROFILE | B42: Preferred Creator Values | C42: preferred_creator_values | D42: Innovation, Trust, Quality, Transparency, Empowerment | E42: Authenticity, Quality, Trust, Health, Craftsmanship | F42: Fun, Community, Authenticity, Family, Affordability | G42: =INDEX($D42:$F42,1,$H$4) -> Innovation, Trust, Quality, Transparency, Empowerment | H42: Up to 5 items, comma-separated
...

Sheet Campaign_Profile
A1: CAMPAIGN PROFILE · campaign is a context layer on top of Brand Match
A2: Brand defines the long-term identity; Campaign defines the specific activation. Style and personality remain explicit inputs, while Campaign Fit captures objective-specific requirements.
A4: Field | B4: Campaign A | C4: Campaign B | D4: Campaign C
A5: Campaign ID | B5: CAMP-A | C5: CAMP-B | D5: CAMP-C
A6: Brand ID | B6: BRAND-A | C6: BRAND-B | D6: BRAND-C
A7: Campaign Name | B7: Tech Productivity Launch | C7: Glow Up Routine | D7: Everyday Meal Moment
A8: Objective | B8: Awareness | C8: Engagement | D8: Conversion
A9: Platform | B9: Instagram | C9: TikTok | D9: Instagram
A10: Target Age | B10: 18-24 | C10: 18-24 | D10: 25-34
A11: Gender | B11: Balanced | C11: Female | D11: Balanced
A12: Target Country | B12: Indonesia | C12: Indonesia | D12: Indonesia
A13: Campaign Category | B13: Tech | C13: Beauty | D13: Food
A14: Key Topics | B14: Technology, Productivity, Business | C14: Skincare, Beauty, Makeup | D14: Food, Lifestyle, Cooking
A15: Content Style | B15: Educational | C15: Tutorial | D15: Review
... A20: Campaign Type | B20: Product Launch | C20: Engagement Challenge | D20: Conversion Campaign
A22: EDITABLE DEFAULT: Campaign Weight in Unified_Match = 30%; Base Brand Match = 70%.

Sheet Campaign_Match
A4: Campaign ID | B4: Brand ID | C4: KOL ID | D4: Creator | E4: Platform | F4: Category | G4: Brand Match | H4: Audience Fit | I4: Style Fit | J4: Personality Fit | K4: Tone Fit | L4: Comm. Style Fit | M4: Campaign Fit | N4: Unified Match | O4: Match Level | P4: Campaign Reason
A5: =Campaign_Profile!$B$5 -> CAMP-A | B5: =Campaign_Profile!$B$6 -> BRAND-A | C5: =KOL_Database!$A$5 -> KOL-01 | D5: =KOL_Database!$B$5 -> Ardi Nugraha | E5: =KOL_Database!$D$5 -> Instagram | F5: =KOL_Database!$E$5 -> Tech | G5: =IFERROR(INDEX(Matching_Engine!$AY$6:$AY$95,MATCH($B5&"|"&$C5,Matching_Engine!$AZ$6:$AZ$95,0)),0) -> 80 | H5: =IFERROR(INDEX(Matching_Engine!$S$6:$S$95,MATCH($B5&"|"&$C5,Matching_Engine!$AZ$6:$AZ$95,0)),0) -> 83 | I5: =IFERROR(INDEX(Matching_Engine!$W$6:$W$95,MATCH($B5&"|"&$C5,Matching_Engine!$AZ$6:$AZ$95,0)),0) -> 80 | J5: =IFERROR(INDEX(Matching_Engine!$Y$6:$Y$95,MATCH($B5&"|"&$C5,Matching_Engine!$AZ$6:$AZ$95,0)),0) -> 85 | K5: =IFERROR(INDEX(Matching_Engine!$Z$6:$Z$95,MATCH($B5&"|"&$C5,Matching_Engine!$AZ$6:$AZ$95,0)),0) -> 90 | L5: =IFERROR(INDEX(Matching_Engine!$AB$6:$AB$95,MATCH($B5&"|"&$C5,Matching_Engine!$AZ$6:$AZ$95,0)),0) -> 70 | M5: =ROUND($H5*0.3+$I5*0.3+$J5*0.25+$L5*0.15,1) -> 80.7 | N5: =ROUND($G5*0.7+$M5*0.3,1) -> 80.2 | O5: =IF($N5>=85,"Excellent Match",IF($N5>=70,"Strong Match",IF($N5>=55,"Good Match","Weak Match"))) -> Strong Match | P5: ="Brand "&ROUND($G5,0)&"/100; Audience "&ROUND($H5,0)&"/100; Style "&ROUND($I5,0)&"/100; Personality "&ROUND($J5,0)&"/100. Campaign Fit "&ROUND($M5,0)&"/100." -> Brand 80/100; Audience 83/100; Style 80/100; Personality 85/100. Campaign Fit 81/100.
A6: =Campaign_Profile!$B$5 -> CAMP-A | B6: =Campaign_Profile!$B$6 -> BRAND-A | C6: =KOL_Database!$A$6 -> KOL-02 | D6: =KOL_Database!$B$6 -> Rifqi Pratama | E6: =KOL_Database!$D$6 -> TikTok | F6: =KOL_Database!$E$6 -> Tech | G6: =IFERROR(INDEX(Matching_Engine!$AY$6:$AY$95,MATCH($B6&"|"&$C6,Matching_Engine!$AZ$6:$AZ$95,0)),0) -> 93 | H6: =IFERROR(INDEX(Matching_Engine!$S$6:$S$95,MATCH($B6&"|"&$C6,Matching_Engine!$AZ$6:$AZ$95,0)),0) -> 91 | I6: =IFERROR(INDEX(Matching_Engine!$W$6:$W$95,MATCH($B6&"|"&$C6,Matching_Engine!$AZ$6:$AZ$95,0)),0) -> 100 | J6: =IFERROR(INDEX(Matching_Engine!$Y$6:$Y$95,MATCH($B6&"|"&$C6,Matching_Engine!$AZ$6:$AZ$95,0)),0) -> 95 | K6: =IFERROR(INDEX(Matching_Engine!$Z$6:$Z$95,MATCH($B6&"|"&$C6,Matching_Engine!$AZ$6:$AZ$95,0)),0) -> 100 | L6: =IFERROR(INDEX(Matching_Engine!$AB$6:$AB$95,MATCH($B6&"|"&$C6,Matching_Engine!$AZ$6:$AZ$95,0)),0) -> 100 | M6: =ROUND($H6*0.3+$I6*0.3+$J6*0.25+$L6*0.15,1) -> 96.1 | N6: =ROUND($G6*0.7+$M6*0.3,1) -> 93.9 | O6: =IF($N6>=85,"Excellent Match",IF($N6>=70,"Strong Match",IF($N6>=55,"Good Match","Weak Match"))) -> Excellent Match | P6: ="Brand "&ROUND($G6,0)&"/100; Audience "&ROUND($H6,0)&"/100; Style "&ROUND($I6,0)&"/100; Personality "&ROUND($J6,0)&"/100. Campaign Fit "&ROUND($M6,0)&"/100." -> Brand 93/100; Audience 91/100; Style 100/100; Personality 95/100. Campaign Fit 96/100.
A7: =Campaign_Profile!$B$5 -> CAMP-A | B7: =Campaign_Profile!$B$6 -> BRAND-A | C7: =KOL_Database!$A$7 -> KOL-03 | D7: =KOL_Database!$B$7 -> Salsa Aulia | E7: =KOL_Database!$D$7 -> Instagram | F7: =KOL_Database!$E$7 -> Beauty | G7: =IFERROR(INDEX(Matching_Engine!$AY$6:$AY$95,MATCH($B7&"|"&$C7,Matching_Engine!$AZ$6:$AZ$95,0)),0) -> 48 | H7: =IFERROR(INDEX(Matching_Engine!$S$6:$S$95,MATCH($B7&"|"&$C7,Matching_Engine!$AZ$6:$AZ$95,0)),0) -> 58 | I7: =IFERROR(INDEX(Matching_Engine!$W$6:$W$95,MATCH($B7&"|"&$C7,Matching_Engine!$AZ$6:$AZ$95,0)),0) -> 80 | J7: =IFERROR(INDEX(Matching_Engine!$Y$6:$Y$95,MATCH($B7&"|"&$C7,Matching_Engine!$AZ$6:$AZ$95,0)),0) -> 85 | K7: =IFERROR(INDEX(Matching_Engine!$Z$6:$Z$95,MATCH($B7&"|"&$C7,Matching_Engine!$AZ$6:$AZ$95,0)),0) -> 90 | L7: =IFERROR(INDEX(Matching_Engine!$AB$6:$AB$95,MATCH($B7&"|"&$C7,Matching_Engine!$AZ$6:$AZ$95,0)),0) -> 70 | M7: =ROUND($H7*0.3+$I7*0.3+$J7*0.25+$L7*0.15,1) -> 73.2 | N7: =ROUND($G7*0.7+$M7*0.3,1) -> 55.6 | O7: =IF($N7>=85,"Excellent Match",IF($N7>=70,"Strong Match",IF($N7>=55,"Good Match","Weak Match"))) -> Good Match | P7: ="Brand "&ROUND($G7,0)&"/100; Audience "&ROUND($H7,0)&"/100; Style "&ROUND($I7,0)&"/100; Personality "&ROUND($J7,0)&"/100. Campaign Fit "&ROUND($M7,0)&"/100." -> Brand 48/100; Audience 58/100; Style 80/100; Personality 85/100. Campaign Fit 73/100.
A8: =Campaign_Profile!$B$5 -> CAMP-A | B8: =Campaign_Profile!$B$6 -> BRAND-A | C8: =KOL_Database!$A$8 -> KOL-04 | D8: =KOL_Database!$B$8 -> Nadia Puspa | E8: =KOL_Database!$D$8 -> TikTok | F8: =KOL_Database!$E$8 -> Beauty | G8: =IFERROR(INDEX(Matching_Engine!$AY$6:$AY$95,MATCH($B8&"|"&$C8,Matching_Engine!$AZ$6:$AZ$95,0)),0) -> 46 | H8: =IFERROR(INDEX(Matching_Engine!$S$6:$S$95,MATCH($B8&"|"&$C8,Matching_Engine!$AZ$6:$AZ$95,0)),0) -> 49 | I8: =IFERROR(INDEX(Matching_Engine!$W$6:$W$95,MATCH($B8&"|"&$C8,Matching_Engine!$AZ$6:$AZ$95,0)),0) -> 80 | J8: =IFERROR(INDEX(Matching_Engine!$Y$6:$Y$95,MATCH($B8&"|"&$C8,Matching_Engine!$AZ$6:$AZ$95,0)),0) -> 95 | K8: =IFERROR(INDEX(Matching_Engine!$Z$6:$Z$95,MATCH($B8&"|"&$C8,Matching_Engine!$AZ$6:$AZ$95,0)),0) -> 95 | L8: =IFERROR(INDEX(Matching_Engine!$AB$6:$AB$95,MATCH($B8&"|"&$C8,Matching_Engine!$AZ$6:$AZ$95,0)),0) -> 95 | M8: =ROUND($H8*0.3+$I8*0.3+$J8*0.25+$L8*0.15,1) -> 76.7 | N8: =ROUND($G8*0.7+$M8*0.3,1) -> 55.2 | O8: =IF($N8>=85,"Excellent Match",IF($N8>=70,"Strong Match",IF($N8>=55,"Good Match","Weak Match"))) -> Good Match | P8: ="Brand "&ROUND($G8,0)&"/100; Audience "&ROUND($H8,0)&"/100; Style "&ROUND($I8,0)&"/100; Personality "&ROUND($J8,0)&"/100. Campaign Fit "&ROUND($M8,0)&"/100." -> Brand 46/100; Audience 49/100; Style 80/100; Personality 95/100. Campaign Fit 77/100.
A9: =Campaign_Profile!$B$5 -> CAMP-A | B9: =Campaign_Profile!$B$6 -> BRAND-A | C9: =KOL_Database!$A$9 -> KOL-05 | D9: =KOL_Database!$B$9 -> Bimo Saputra | E9: =KOL_Database!$D$9 -> TikTok | F9: =KOL_Database!$E$9 -> Food | G9: =IFERROR(INDEX(Matching_Engine!$AY$6:$AY$95,MATCH($B9&"|"&$C9,Matching_Engine!$AZ$6:$AZ$95,0)),0) -> 45 | H9: =IFERROR(INDEX(Matching_Engine!$S$6:$S$95,MATCH($B9&"|"&$C9,Matching_Engine!$AZ$6:$AZ$95,0)),0) -> 54 | I9: =IFERROR(INDEX(Matching_Engine!$W$6:$W$95,MATCH($B9&"|"&$C9,Matching_Engine!$AZ$6:$AZ$95,0)),0) -> 80 | J9: =IFERROR(INDEX(Matching_Engine!$Y$6:$Y$95,MATCH($B9&"|"&$C9,Matching_Engine!$AZ$6:$AZ$95,0)),0) -> 50 | K9: =IFERROR(INDEX(Matching_Engine!$Z$6:$Z$95,MATCH($B9&"|"&$C9,Matching_Engine!$AZ$6:$AZ$95,0)),0) -> 90 | L9: =IFERROR(INDEX(Matching_Engine!$AB$6:$AB$95,MATCH($B9&"|"&$C9,Matching_Engine!$AZ$6:$AZ$95,0)),0) -> 70 | M9: =ROUND($H9*0.3+$I9*0.3+$J9*0.25+$L9*0.15,1) -> 63.2 | N9: =ROUND($G9*0.7+$M9*0.3,1) -> 50.5 | O9: =IF($N9>=85,"Excellent Match",IF($N9>=70,"Strong Match",IF($N9>=55,"Good Match","Weak Match"))) -> Weak Match | P9: ="Brand "&ROUND($G9,0)&"/100; Audience "&ROUND($H9,0)&"/100; Style "&ROUND($I9,0)&"/100; Personality "&ROUND($J9,0)&"/100. Campaign Fit "&ROUND($M9,0)&"/100." -> Brand 45/100; Audience 54/100; Style 80/100; Personality 50/100. Campaign Fit 63/100.
A10: =Campaign_Profile!$B$5 -> CAMP-A | B10: =Campaign_Profile!$B$6 -> BRAND-A | C10: =KOL_Database!$A$10 -> KOL-06 | D10: =KOL_Database!$B$10 -> Ayu Lestari | E10: =KOL_Database!$D$10 -> Instagram | F10: =KOL_Database!$E$10 -> Food | G10: =IFERROR(INDEX(Matching_Engine!$AY$6:$AY$95,MATCH($B10&"|"&$C10,Matching_Engine!$AZ$6:$AZ$95,0)),0) -> 44 | H10: =IFERROR(INDEX(Matching_Engine!$S$6:$S$95,MATCH($B10&"|"&$C10,Matching_Engine!$AZ$6:$AZ$95,0)),0) -> 50 | I10: =IFERROR(INDEX(Matching_Engine!$W$6:$W$95,MATCH($B10&"|"&$C10,Matching_Engine!$AZ$6:$AZ$95,0)),0) -> 80 | J10: =IFERROR(INDEX(Matching_Engine!$Y$6:$Y$95,MATCH($B10&"|"&$C10,Matching_Engine!$AZ$6:$AZ$95,0)),0) -> 50 | K10: =IFERROR(INDEX(Matching_Engine!$Z$6:$Z$95,MATCH($B10&"|"&$C10,Matching_Engine!$AZ$6:$AZ$95,0)),0) -> 95 | L10: =IFERROR(INDEX(Matching_Engine!$AB$6:$AB$95,MATCH($B10&"|"&$C10,Matching_Engine!$AZ$6:$AZ$95,0)),0) -> 95 | M10: =ROUND($H10*0.3+$I10*0.3+$J10*0.25+$L10*0.15,1) -> 65.8 | N10: =ROUND($G10*0.7+$M10*0.3,1) -> 50.5 | O10: =IF($N10>=85,"Excellent Match",IF($N10>=70,"Strong Match",IF($N10>=55,"Good Match","Weak Match"))) -> Weak Match | P10: ="Brand "&ROUND($G10,0)&"/100; Audience "&ROUND($H10,0)&"/100; Style "&ROUND($I10,0)&"/100; Personality "&ROUND($J10,0)&"/100. Campaign Fit "&ROUND($M10,0)&"/100." -> Brand 44/100; Audience 50/100; Style 80/100; Personality 50/100. Campaign Fit 66/100.
A11: =Campaign_Profile!$B$5 -> CAMP-A | B11: =Campaign_Profile!$B$6 -> BRAND-A | C11: =KOL_Database!$A$11 -> KOL-07 | D11: =KOL_Database!$B$11 -> Fajar Ramadhan | E11: =KOL_Database!$D$11 -> Instagram | F11: =KOL_Database!$E$11 -> Finance | G11: =IFERROR(INDEX(Matching_Engine!$AY$6:$AY$95,MATCH($B11&"|"&$C11,Matching_Engine!$AZ$6:$AZ$95,0)),0) -> 87 | H11: =IFERROR(INDEX(Matching_Engine!$S$6:$S$95,MATCH($B11&"|"&$C11,Matching_Engine!$AZ$6:$AZ$95,0)),0) -> 100 | I11: =IFERROR(INDEX(Matching_Engine!$W$6:$W$95,MATCH($B11&"|"&$C11,Matching_Engine!$AZ$6:$AZ$95,0)),0) -> 100 | J11: =IFERROR(INDEX(Matching_Engine!$Y$6:$Y$95,MATCH($B11&"|"&$C11,Matching_Engine!$AZ$6:$AZ$95,0)),0) -> 70 | K11: =IFERROR(INDEX(Matching_Engine!$Z$6:$Z$95,MATCH($B11&"|"&$C11,Matching_Engine!$AZ$6:$AZ$95,0)),0) -> 100 | L11: =IFERROR(INDEX(Matching_Engine!$AB$6:$AB$95,MATCH($B11&"|"&$C11,Matching_Engine!$AZ$6:$AZ$95,0)),0) -> 100 | M11: =ROUND($H11*0.3+$I11*0.3+$J11*0.25+$L11*0.15,1) -> 92.5 | N11: =ROUND($G11*0.7+$M11*0.3,1) -> 88.7 | O11: =IF($N11>=85,"Excellent Match",IF($N11>=70,"Strong Match",IF($N11>=55,"Good Match","Weak Match"))) -> Excellent Match | P11: ="Brand "&ROUND($G11,0)&"/100; Audience "&ROUND($H11,0)&"/100; Style "&ROUND($I11,0)&"/100; Personality "&ROUND($J11,0)&"/100. Campaign Fit "&ROUND($M11,0)&"/100." -> Brand 87/100; Audience 100/100; Style 100/100; Personality 70/100. Campaign Fit 93/100.
A12: =Campaign_Profile!$B$5 -> CAMP-A | B12: =Campaign_Profile!$B$6 -> BRAND-A | C12: =KOL_Database!$A$12 -> KOL-08 | D12: =KOL_Database!$B$12 -> Tania Wijaya | E12: =KOL_Database!$D$12 -> TikTok | F12: =KOL_Database!$E$12 -> Finance | G12: =IFERROR(INDEX(Matching_Engine!$AY$6:$AY$95,MATCH($B12&"|"&$C12,Matching_Engine!$AZ$6:$AZ$95,0)),0) | H12: =IFERROR(INDEX(Matching_Engine!$S$6:$S$95,MATCH($B12&"|"&$C12,Matching_Engine!$AZ$6:$AZ$95,0)),0) -> 92 | I12: =IFERROR(INDEX(Matching_Engine!$W$6:$W$95,MATCH($B12&"|"&$C12,Matching_Engine!$AZ$6:$AZ$95,0)),0) -> 100 | J12: =IFERROR(INDEX(Matching_Engine!$Y$6:$Y$95,MATCH($B12&"|"&$C12,Matching_Engine!$AZ$6:$AZ$95,0)),0) -> 95 | K12: =IFERROR(INDEX(Matching_Engine!$Z$6:$Z$95,MATCH($B12&"|"&$C12,Matching_Engine!$AZ$6:$AZ$95,0)),0) -> 100 | L12: =IFERROR(INDEX(Matching_Engine!$AB$6:$AB$95,MATCH($B12&"|"&$C12,Matching_Engine!$AZ$6:$AZ$95,0)),0) -> 100 | M12: =ROUND($H12*0.3+$I12*0.3+$J12*0.25+$L12*0.15,1) -> 96.4 | N12: =ROUND($G12*0.7+$M12*0.3,1) -> #VALUE! | O12: =IF($N12>=85,"Excellent Match",IF($N12>=70,"Strong Match",IF($N12>=55,"Good Match","Weak Match"))) -> #VALUE! | P12: ="Brand "&ROUND($G12,0)&"/100; Audience "&ROUND($H12,0)&"/100; Style "&ROUND($I12,0)&"/100; Personality "&ROUND($J12,0)&"/100. Campaign Fit "&ROUND($M12,0)&"/100." -> #VALUE!
A13: =Campaign_Profile!$B$5 -> CAMP-A | B13: =Campaign_Profile!$B$6 -> BRAND-A | C13: =KOL_Database!$A$13 -> KOL-09 | D13: =KOL_Database!$B$13 -> Gilang Prakoso | E13: =KOL_Database!$D$13 -> TikTok | F13: =KOL_Database!$E$13 -> Education | G13: =IFERROR(INDEX(Matching_Engine!$AY$6:$AY$95,MATCH($B13&"|"&$C13,Matching_Engine!$AZ$6:$AZ$95,0)),0) -> 81 | H13: =IFERROR(INDEX(Matching_Engine!$S$6:$S$95,MATCH($B13&"|"&$C13,Matching_Engine!$AZ$6:$AZ$95,0)),0) -> 83 | I13: =IFERROR(INDEX(Matching_Engine!$W$6:$W$95,MATCH($B13&"|"&$C13,Matching_Engine!$AZ$6:$AZ$95,0)),0) -> 100 | J13: =IFERROR(INDEX(Matching_Engine!$Y$6:$Y$95,MATCH($B13&"|"&$C13,Matching_Engine!$AZ$6:$AZ$95,0)),0) -> 95 | K13: =IFERROR(INDEX(Matching_Engine!$Z$6:$Z$95,MATCH($B13&"|"&$C13,Matching_Engine!$AZ$6:$AZ$95,0)),0) -> 100 | L13: =IFERROR(INDEX(Matching_Engine!$AB$6:$AB$95,MATCH($B13&"|"&$C13,Matching_Engine!$AZ$6:$AZ$95,0)),0) -> 100 | M13: =ROUND($H13*0.3+$I13*0.3+$J13*0.25+$L13*0.15,1) -> 93.7 | N13: =ROUND($G13*0.7+$M13*0.3,1) -> 84.8 | O13: =IF($N13>=85,"Excellent Match",IF($N13>=70,"Strong Match",IF($N13>=55,"Good Match","Weak Match"))) -> Strong Match | P13: ="Brand "&ROUND($G13,0)&"/100; Audience "&ROUND($H13,0)&"/100; Style "&ROUND($I13,0)&"/100; Personality "&ROUND($J13,0)&"/100. Campaign Fit "&ROUND($M13,0)&"/100." -> Brand 81/100; Audience 83/100; Style 100/100; Personality 95/100. Campaign Fit 94/100.
A14: =Campaign_Profile!$B$5 -> CAMP-A | B14: =Campaign_Profile!$B$6 -> BRAND-A | C14: =KOL_Database!$A$14 -> KOL-10 | D14: =KOL_Database!$B$14 -> Mira Handayani | E14: =KOL_Database!$D$14 -> Instagram | F14: =KOL_Database!$E$14 -> Education | G14: =IFERROR(INDEX(Matching_Engine!$AY$6:$AY$95,MATCH($B14&"|"&$C14,Matching_Engine!$AZ$6:$AZ$95,0)),0) -> 74 | H14: =IFERROR(INDEX(Matching_Engine!$S$6:$S$95,MATCH($B14&"|"&$C14,Matching_Engine!$AZ$6:$AZ$95,0)),0) -> 74 | I14: =IFERROR(INDEX(Matching_Engine!$W$6:$W$95,MATCH($B14&"|"&$C14,Matching_Engine!$AZ$6:$AZ$95,0)),0) -> 80 | J14: =IFERROR(INDEX(Matching_Engine!$Y$6:$Y$95,MATCH($B14&"|"&$C14,Matching_Engine!$AZ$6:$AZ$95,0)),0) -> 95 | K14: =IFERROR(INDEX(Matching_Engine!$Z$6:$Z$95,MATCH($B14&"|"&$C14,Matching_Engine!$AZ$6:$AZ$95,0)),0) -> 95 | L14: =IFERROR(INDEX(Matching_Engine!$AB$6:$AB$95,MATCH($B14&"|"&$C14,Matching_Engine!$AZ$6:$AZ$95,0)),0) -> 95 | M14: =ROUND($H14*0.3+$I14*0.3+$J14*0.25+$L14*0.15,1) -> 84.2 | N14: =ROUND($G14*0.7+$M14*0.3,1) -> 77.1 | O14: =IF($N14>=85,"Excellent Match",IF($N14>=70,"Strong Match",IF($N14>=55,"Good Match","Weak Match"))) -> Strong Match | P14: ="Brand "&ROUND($G14,0)&"/100; Audience "&ROUND($H14,0)&"/100; Style "&ROUND($I14,0)&"/100; Personality "&ROUND($J14,0)&"/100. Campaign Fit "&ROUND($M14,0)&"/100." -> Brand 74/100; Audience 74/100; Style 80/100; Personality 95/100. Campaign Fit 84/100.
A15: =Campaign_Profile!$B$5 -> CAMP-A | B15: =Campaign_Profile!$B$6 -> BRAND-A | C15: =KOL_Database!$A$15 -> KOL-11 | D15: =KOL_Database!$B$15 -> Dimas Anggara | E15: =KOL_Database!$D$15 -> Instagram | F15: =KOL_Database!$E$15 -> Fitness | G15: =IFERROR(INDEX(Matching_Engine!$AY$6:$AY$95,MATCH($B15&"|"&$C15,Matching_Engine!$AZ$6:$AZ$95,0)),0) | H15: =IFERROR(INDEX(Matching_Engine!$S$6:$S$95,MATCH($B15&"|"&$C15,Matching_Engine!$AZ$6:$AZ$95,0)),0) -> 58 | I15: =IFERROR(INDEX(Matching_Engine!$W$6:$W$95,MATCH($B15&"|"&$C15,Matching_Engine!$AZ$6:$AZ$95,0)),0) -> 80 | J15: =IFERROR(INDEX(Matching_Engine!$Y$6:$Y$95,MATCH($B15&"|"&$C15,Matching_Engine!$AZ$6:$AZ$95,0)),0) -> 70 | K15: =IFERROR(INDEX(Matching_Engine!$Z$6:$Z$95,MATCH($B15&"|"&$C15,Matching_Engine!$AZ$6:$AZ$95,0)),0) -> 85 | L15: =IFERROR(INDEX(Matching_Engine!$AB$6:$AB$95,MATCH($B15&"|"&$C15,Matching_Engine!$AZ$6:$AZ$95,0)),0) -> 80 | M15: =ROUND($H15*0.3+$I15*0.3+$J15*0.25+$L15*0.15,1) -> 70.9 | N15: =ROUND($G15*0.7+$M15*0.3,1) -> #VALUE! | O15: =IF($N15>=85,"Excellent Match",IF($N15>=70,"Strong Match",IF($N15>=55,"Good Match","Weak Match"))) -> #VALUE! | P15: ="Brand "&ROUND($G15,0)&"/100; Audience "&ROUND($H15,0)&"/100; Style "&ROUND($I15,0)&"/100; Personality "&ROUND($J15,0)&"/100. Campaign Fit "&ROUND($M15,0)&"/100." -> #VALUE!
A16: =Campaign_Profile!$B$5 -> CAMP-A | B16: =Campaign_Profile!$B$6 -> BRAND-A | C16: =KOL_Database!$A$16 -> KOL-12 | D16: =KOL_Database!$B$16 -> Rani Kusuma | E16: =KOL_Database!$D$16 -> TikTok | F16: =KOL_Database!$E$16 -> Fitness | G16: =IFERROR(INDEX(Matching_Engine!$AY$6:$AY$95,MATCH($B16&"|"&$C16,Matching_Engine!$AZ$6:$AZ$95,0)),0) -> 48 | H16: =IFERROR(INDEX(Matching_Engine!$S$6:$S$95,MATCH($B16&"|"&$C16,Matching_Engine!$AZ$6:$AZ$95,0)),0) -> 49 | I16: =IFERROR(INDEX(Matching_Engine!$W$6:$W$95,MATCH($B16&"|"&$C16,Matching_Engine!$AZ$6:$AZ$95,0)),0) -> 80 | J16: =IFERROR(INDEX(Matching_Engine!$Y$6:$Y$95,MATCH($B16&"|"&$C16,Matching_Engine!$AZ$6:$AZ$95,0)),0) -> 70 | K16: =IFERROR(INDEX(Matching_Engine!$Z$6:$Z$95,MATCH($B16&"|"&$C16,Matching_Engine!$AZ$6:$AZ$95,0)),0) -> 95 | L16: =IFERROR(INDEX(Matching_Engine!$AB$6:$AB$95,MATCH($B16&"|"&$C16,Matching_Engine!$AZ$6:$AZ$95,0)),0) -> 95 | M16: =ROUND($H16*0.3+$I16*0.3+$J16*0.25+$L16*0.15,1) -> 70.5 | N16: =ROUND($G16*0.7+$M16*0.3,1) -> 54.8 | O16: =IF($N16>=85,"Excellent Match",IF($N16>=70,"Strong Match",IF($N16>=55,"Good Match","Weak Match"))) -> Weak Match | P16: ="Brand "&ROUND($G16,0)&"/100; Audience "&ROUND($H16,0)&"/100; Style "&ROUND($I16,0)&"/100; Personality "&ROUND($J16,0)&"/100. Campaign Fit "&ROUND($M16,0)&"/100." -> Brand 48/100; Audience 49/100; Style 80/100; Personality 70/100. Campaign Fit 71/100.
A17: =Campaign_Profile!$B$5 -> CAMP-A | B17: =Campaign_Profile!$B$6 -> BRAND-A | C17: =KOL_Database!$A$17 -> KOL-13 | D17: =KOL_Database!$B$17 -> Kevin Halim | E17: =KOL_Database!$D$17 -> Instagram | F17: =KOL_Database!$E$17 -> Fashion | G17: =IFERROR(INDEX(Matching_Engine!$AY$6:$AY$95,MATCH($B17&"|"&$C17,Matching_Engine!$AZ$6:$AZ$95,0)),0) -> 45 | H17: =IFERROR(INDEX(Matching_Engine!$S$6:$S$95,MATCH($B17&"|"&$C17,Matching_Engine!$AZ$6:$AZ$95,0)),0) -> 58 | I17: =IFERROR(INDEX(Matching_Engine!$W$6:$W$95,MATCH($B17&"|"&$C17,Matching_Engine!$AZ$6:$AZ$95,0)),0) -> 45 | J17: =IFERROR(INDEX(Matching_Engine!$Y$6:$Y$95,MATCH($B17&"|"&$C17,Matching_Engine!$AZ$6:$AZ$95,0)),0) -> 95 | K17: =IFERROR(INDEX(Matching_Engine!$Z$6:$Z$95,MATCH($B17&"|"&$C17,Matching_Engine!$AZ$6:$AZ$95,0)),0) -> 50 | L17: =IFERROR(INDEX(Matching_Engine!$AB$6:$AB$95,MATCH($B17&"|"&$C17,Matching_Engine!$AZ$6:$AZ$95,0)),0) -> 45 | M17: =ROUND($H17*0.3+$I17*0.3+$J17*0.25+$L17*0.15,1) -> 61.4 | N17: =ROUND($G17*0.7+$M17*0.3,1) -> 49.9 | O17: =IF($N17>=85,"Excellent Match",IF($N17>=70,"Strong Match",IF($N17>=55,"Good Match","Weak Match"))) -> Weak Match | P17: ="Brand "&ROUND($G17,0)&"/100; Audience "&ROUND($H17,0)&"/100; Style "&ROUND($I17,0)&"/100; Personality "&ROUND($J17,0)&"/100. Campaign Fit "&ROUND($M17,0)&"/100." -> Brand 45/100; Audience 58/100; Style 45/100; Personality 95/100. Campaign Fit 61/100.
A18: =Campaign_Profile!$B$5 -> CAMP-A | B18: =Campaign_Profile!$B$6 -> BRAND-A | C18: =KOL_Database!$A$18 -> KOL-14 | D18: =KOL_Database!$B$18 -> Zahra Amelia | E18: =KOL_Database!$D$18 -> Instagram | F18: =KOL_Database!$E$18 -> Fashion | G18: =IFERROR(INDEX(Matching_Engine!$AY$6:$AY$95,MATCH($B18&"|"&$C18,Matching_Engine!$AZ$6:$AZ$95,0)),0) | H18: =IFERROR(INDEX(Matching_Engine!$S$6:$S$95,MATCH($B18&"|"&$C18,Matching_Engine!$AZ$6:$AZ$95,0)),0) -> 49 | I18: =IFERROR(INDEX(Matching_Engine!$W$6:$W$95,MATCH($B18&"|"&$C18,Matching_Engine!$AZ$6:$AZ$95,0)),0) -> 45 | J18: =IFERROR(INDEX(Matching_Engine!$Y$6:$Y$95,MATCH($B18&"|"&$C18,Matching_Engine!$AZ$6:$AZ$95,0)),0) -> 60 | K18: =IFERROR(INDEX(Matching_Engine!$Z$6:$Z$95,MATCH($B18&"|"&$C18,Matching_Engine!$AZ$6:$AZ$95,0)),0) -> 50 | L18: =IFERROR(INDEX(Matching_Engine!$AB$6:$AB$95,MATCH($B18&"|"&$C18,Matching_Engine!$AZ$6:$AZ$95,0)),0) -> 45 | M18: =ROUND($H18*0.3+$I18*0.3+$J18*0.25+$L18*0.15,1) -> 50 | N18: =ROUND($G18*0.7+$M18*0.3,1) -> #VALUE! | O18: =IF($N18>=85,"Excellent Match",IF($N18>=70,"Strong Match",IF($N18>=55,"Good Match","Weak Match"))) -> #VALUE! | P18: ="Brand "&ROUND($G18,0)&"/100; Audience "&ROUND($H18,0)&"/100; Style "&ROUND($I18,0)&"/100; Personality "&ROUND($J18,0)&"/100. Campaign Fit "&ROUND($M18,0)&"/100." -> #VALUE!
A19: =Campaign_Profile!$B$5 -> CAMP-A | B19: =Campaign_Profile!$B$6 -> BRAND-A | C19: =KOL_Database!$A$19 -> KOL-15 | D19: =KOL_Database!$B$19 -> Andini Rahma | E19: =KOL_Database!$D$19 -> Instagram | F19: =KOL_Database!$E$19 -> Lifestyle | G19: =IFERROR(INDEX(Matching_Engine!$AY$6:$AY$95,MATCH($B19&"|"&$C19,Matching_Engine!$AZ$6:$AZ$95,0)),0) -> 48 | H19: =IFERROR(INDEX(Matching_Engine!$S$6:$S$95,MATCH($B19&"|"&$C19,Matching_Engine!$AZ$6:$AZ$95,0)),0) -> 58 | I19: =IFERROR(INDEX(Matching_Engine!$W$6:$W$95,MATCH($B19&"|"&$C19,Matching_Engine!$AZ$6:$AZ$95,0)),0) -> 45 | J19: =IFERROR(INDEX(Matching_Engine!$Y$6:$Y$95,MATCH($B19&"|"&$C19,Matching_Engine!$AZ$6:$AZ$95,0)),0) -> 50 | K19: =IFERROR(INDEX(Matching_Engine!$Z$6:$Z$95,MATCH($B19&"|"&$C19,Matching_Engine!$AZ$6:$AZ$95,0)),0) -> 55 | L19: =IFERROR(INDEX(Matching_Engine!$AB$6:$AB$95,MATCH($B19&"|"&$C19,Matching_Engine!$AZ$6:$AZ$95,0)),0) -> 50 | M19: =ROUND($H19*0.3+$I19*0.3+$J19*0.25+$L19*0.15,1) -> 50.9 | N19: =ROUND($G19*0.7+$M19*0.3,1) -> 48.9 | O19: =IF($N19>=85,"Excellent Match",IF($N19>=70,"Strong Match",IF($N19>=55,"Good Match","Weak Match"))) -> Weak Match | P19: ="Brand "&ROUND($G19,0)&"/100; Audience "&ROUND($H19,0)&"/100; Style "&ROUND($I19,0)&"/100; Personality "&ROUND($J19,0)&"/100. Campaign Fit "&ROUND($M19,0)&"/100." -> Brand 48/100; Audience 58/100; Style 45/100; Personality 50/100. Campaign Fit 51/100.
A20: =Campaign_Profile!$B$5 -> CAMP-A | B20: =Campaign_Profile!$B$6 -> BRAND-A | C20: =KOL_Database!$A$20 -> KOL-16 | D20: =KOL_Database!$B$20 -> Yoga Pratama | E20: =KOL_Database!$D$20 -> TikTok | F20: =KOL_Database!$E$20 -> Lifestyle | G20: =IFERROR(INDEX(Matching_Engine!$AY$6:$AY$95,MATCH($B20&"|"&$C20,Matching_Engine!$AZ$6:$AZ$95,0)),0) -> 67 | H20: =IFERROR(INDEX(Matching_Engine!$S$6:$S$95,MATCH($B20&"|"&$C20,Matching_Engine!$AZ$6:$AZ$95,0)),0) -> 83 | I20: =IFERROR(INDEX(Matching_Engine!$W$6:$W$95,MATCH($B20&"|"&$C20,Matching_Engine!$AZ$6:$AZ$95,0)),0) -> 45 | J20: =IFERROR(INDEX(Matching_Engine!$Y$6:$Y$95,MATCH($B20&"|"&$C20,Matching_Engine!$AZ$6:$AZ$95,0)),0) -> 70 | K20: =IFERROR(INDEX(Matching_Engine!$Z$6:$Z$95,MATCH($B20&"|"&$C20,Matching_Engine!$AZ$6:$AZ$95,0)),0) -> 65 | L20: =IFERROR(INDEX(Matching_Engine!$AB$6:$AB$95,MATCH($B20&"|"&$C20,Matching_Engine!$AZ$6:$AZ$95,0)),0) -> 60 | M20: =ROUND($H20*0.3+$I20*0.3+$J20*0.25+$L20*0.15,1) -> 64.9 | N20: =ROUND($G20*0.7+$M20*0.3,1) -> 66.4 | O20: =IF($N20>=85,"Excellent Match",IF($N20>=70,"Strong Match",IF($N20>=55,"Good Match","Weak Match"))) -> Good Match | P20: ="Brand "&ROUND($G20,0)&"/100; Audience "&ROUND($H20,0)&"/100; Style "&ROUND($I20,0)&"/100; Personality "&ROUND($J20,0)&"/100. Campaign Fit "&ROUND($M20,0)&"/100." -> Brand 67/100; Audience 83/100; Style 45/100; Personality 70/100. Campaign Fit 65/100.
A21: =Campaign_Profile!$B$5 -> CAMP-A | B21: =Campaign_Profile!$B$6 -> BRAND-A | C21: =KOL_Database!$A$21 -> KOL-17 | D21: =KOL_Database!$B$21 -> Sinta Maharani | E21: =KOL_Database!$D$21 -> Instagram | F21: =KOL_Database!$E$21 -> Travel | G21: =IFERROR(INDEX(Matching_Engine!$AY$6:$AY$95,MATCH($B21&"|"&$C21,Matching_Engine!$AZ$6:$AZ$95,0)),0) -> 42 | H21: =IFERROR(INDEX(Matching_Engine!$S$6:$S$95,MATCH($B21&"|"&$C21,Matching_Engine!$AZ$6:$AZ$95,0)),0) -> 49 | I21: =IFERROR(INDEX(Matching_Engine!$W$6:$W$95,MATCH($B21&"|"&$C21,Matching_Engine!$AZ$6:$AZ$95,0)),0) -> 45 | J21: =IFERROR(INDEX(Matching_Engine!$Y$6:$Y$95,MATCH($B21&"|"&$C21,Matching_Engine!$AZ$6:$AZ$95,0)),0) -> 60 | K21: =IFERROR(INDEX(Matching_Engine!$Z$6:$Z$95,MATCH($B21&"|"&$C21,Matching_Engine!$AZ$6:$AZ$95,0)),0) -> 50 | L21: =IFERROR(INDEX(Matching_Engine!$AB$6:$AB$95,MATCH($B21&"|"&$C21,Matching_Engine!$AZ$6:$AZ$95,0)),0) -> 45 | M21: =ROUND($H21*0.3+$I21*0.3+$J21*0.25+$L21*0.15,1) -> 50 | N21: =ROUND($G21*0.7+$M21*0.3,1) -> 44.4 | O21: =IF($N21>=85,"Excellent Match",IF($N21>=70,"Strong Match",IF($N21>=55,"Good Match","Weak Match"))) -> Weak Match | P21: ="Brand "&ROUND($G21,0)&"/100; Audience "&ROUND($H21,0)&"/100; Style "&ROUND($I21,0)&"/100; Personality "&ROUND($J21,0)&"/100. Campaign Fit "&ROUND($M21,0)&"/100." -> Brand 42/100; Audience 49/100; Style 45/100; Personality 60/100. Campaign Fit 50/100.
A22: =Campaign_Profile!$B$5 -> CAMP-A | B22: =Campaign_Profile!$B$6 -> BRAND-A | C22: =KOL_Database!$A$22 -> KOL-18 | D22: =KOL_Database!$B$22 -> Reza Fadillah | E22: =KOL_Database!$D$22 -> TikTok | F22: =KOL_Database!$E$22 -> Travel | G22: =IFERROR(INDEX(Matching_Engine!$AY$6:$AY$95,MATCH($B22&"|"&$C22,Matching_Engine!$AZ$6:$AZ$95,0)),0) -> 48 | H22: =IFERROR(INDEX(Matching_Engine!$S$6:$S$95,MATCH($B22&"|"&$C22,Matching_Engine!$AZ$6:$AZ$95,0)),0) -> 57 | I22: =IFERROR(INDEX(Matching_Engine!$W$6:$W$95,MATCH($B22&"|"&$C22,Matching_Engine!$AZ$6:$AZ$95,0)),0) -> 45 | J22: =IFERROR(INDEX(Matching_Engine!$Y$6:$Y$95,MATCH($B22&"|"&$C22,Matching_Engine!$AZ$6:$AZ$95,0)),0) -> 40 | K22: =IFERROR(INDEX(Matching_Engine!$Z$6:$Z$95,MATCH($B22&"|"&$C22,Matching_Engine!$AZ$6:$AZ$95,0)),0) -> 55 | L22: =IFERROR(INDEX(Matching_Engine!$AB$6:$AB$95,MATCH($B22&"|"&$C22,Matching_Engine!$AZ$6:$AZ$95,0)),0) -> 50 | M22: =ROUND($H22*0.3+$I22*0.3+$J22*0.25+$L22*0.15,1) -> 48.1 | N22: =ROUND($G22*0.7+$M22*0.3,1) -> 48 | O22: =IF($N22>=85,"Excellent Match",IF($N22>=70,"Strong Match",IF($N22>=55,"Good Match","Weak Match"))) -> Weak Match | P22: ="Brand "&ROUND($G22,0)&"/100; Audience "&ROUND($H22,0)&"/100; Style "&ROUND($I22,0)&"/100; Personality "&ROUND($J22,0)&"/100. Campaign Fit "&ROUND($M22,0)&"/100." -> Brand 48/100; Audience 57/100; Style 45/100; Personality 40/100. Campaign Fit 48/100.
A23: =Campaign_Profile!$B$5 -> CAMP-A | B23: =Campaign_Profile!$B$6 -> BRAND-A | C23: =KOL_Database!$A$23 -> KOL-19 | D23: =KOL_Database!$B$23 -> Putri Amanda | E23: =KOL_Database!$D$23 -> Instagram | F23: =KOL_Database!$E$23 -> Parenting | G23: =IFERROR(INDEX(Matching_Engine!$AY$6:$AY$95,MATCH($B23&"|"&$C23,Matching_Engine!$AZ$6:$AZ$95,0)),0) -> 41 | H23: =IFERROR(INDEX(Matching_Engine!$S$6:$S$95,MATCH($B23&"|"&$C23,Matching_Engine!$AZ$6:$AZ$95,0)),0) -> 49 | I23: =IFERROR(INDEX(Matching_Engine!$W$6:$W$95,MATCH($B23&"|"&$C23,Matching_Engine!$AZ$6:$AZ$95,0)),0) -> 45 | J23: =IFERROR(INDEX(Matching_Engine!$Y$6:$Y$95,MATCH($B23&"|"&$C23,Matching_Engine!$AZ$6:$AZ$95,0)),0) -> 50 | K23: =IFERROR(INDEX(Matching_Engine!$Z$6:$Z$95,MATCH($B23&"|"&$C23,Matching_Engine!$AZ$6:$AZ$95,0)),0) -> 65 | L23: =IFERROR(INDEX(Matching_Engine!$AB$6:$AB$95,MATCH($B23&"|"&$C23,Matching_Engine!$AZ$6:$AZ$95,0)),0) -> 60 | M23: =ROUND($H23*0.3+$I23*0.3+$J23*0.25+$L23*0.15,1) -> 49.7 | N23: =ROUND($G23*0.7+$M23*0.3,1) -> 43.6 | O23: =IF($N23>=85,"Excellent Match",IF($N23>=70,"Strong Match",IF($N23>=55,"Good Match","Weak Match"))) -> Weak Match | P23: ="Brand "&ROUND($G23,0)&"/100; Audience "&ROUND($H23,0)&"/100; Style "&ROUND($I23,0)&"/100; Personality "&ROUND($J23,0)&"/100. Campaign Fit "&ROUND($M23,0)&"/100." -> Brand 41/100; Audience 49/100; Style 45/100; Personality 50/100. Campaign Fit 50/100.
A24: =Campaign_Profile!$B$5 -> CAMP-A | B24: =Campaign_Profile!$B$6 -> BRAND-A | C24: =KOL_Database!$A$24 -> KOL-20 | D24: =KOL_Database!$B$24 -> Hendra Wijoyo | E24: =KOL_Database!$D$24 -> TikTok | F24: =KOL_Database!$E$24 -> Parenting | G24: =IFERROR(INDEX(Matching_Engine!$AY$6:$AY$95,MATCH($B24&"|"&$C24,Matching_Engine!$AZ$6:$AZ$95,0)),0) -> 45 | H24: =IFERROR(INDEX(Matching_Engine!$S$6:$S$95,MATCH($B24&"|"&$C24,Matching_Engine!$AZ$6:$AZ$95,0)),0) -> 57 | I24: =IFERROR(INDEX(Matching_Engine!$W$6:$W$95,MATCH($B24&"|"&$C24,Matching_Engine!$AZ$6:$AZ$95,0)),0) -> 45 | J24: =IFERROR(INDEX(Matching_Engine!$Y$6:$Y$95,MATCH($B24&"|"&$C24,Matching_Engine!$AZ$6:$AZ$95,0)),0) -> 30 | K24: =IFERROR(INDEX(Matching_Engine!$Z$6:$Z$95,MATCH($B24&"|"&$C24,Matching_Engine!$AZ$6:$AZ$95,0)),0) -> 40 | L24: =IFERROR(INDEX(Matching_Engine!$AB$6:$AB$95,MATCH($B24&"|"&$C24,Matching_Engine!$AZ$6:$AZ$95,0)),0) -> 40 | M24: =ROUND($H24*0.3+$I24*0.3+$J24*0.25+$L24*0.15,1) -> 44.1 | N24: =ROUND($G24*0.7+$M24*0.3,1) -> 44.7 | O24: =IF($N24>=85,"Excellent Match",IF($N24>=70,"Strong Match",IF($N24>=55,"Good Match","Weak Match"))) -> Weak Match | P24: ="Brand "&ROUND($G24,0)&"/100; Audience "&ROUND($H24,0)&"/100; Style "&ROUND($I24,0)&"/100; Personality "&ROUND($J24,0)&"/100. Campaign Fit "&ROUND($M24,0)&"/100." -> Brand 45/100; Audience 57/100; Style 45/100; Personality 30/100. Campaign Fit 44/100.
A25: =Campaign_Profile!$B$5 -> CAMP-A | B25: =Campaign_Profile!$B$6 -> BRAND-A | C25: =KOL_Database!$A$25 -> KOL-21 | D25: =KOL_Database!$B$25 -> Bagas Setiawan | E25: =KOL_Database!$D$25 -> TikTok | F25: =KOL_Database!$E$25 -> Entertainment | G25: =IFERROR(INDEX(Matching_Engine!$AY$6:$AY$95,MATCH($B25&"|"&$C25,Matching_Engine!$AZ$6:$AZ$95,0)),0) | H25: =IFERROR(INDEX(Matching_Engine!$S$6:$S$95,MATCH($B25&"|"&$C25,Matching_Engine!$AZ$6:$AZ$95,0)),0) -> 49 | I25: =IFERROR(INDEX(Matching_Engine!$W$6:$W$95,MATCH($B25&"|"&$C25,Matching_Engine!$AZ$6:$AZ$95,0)),0) -> 45 | J25: =IFERROR(INDEX(Matching_Engine!$Y$6:$Y$95,MATCH($B25&"|"&$C25,Matching_Engine!$AZ$6:$AZ$95,0)),0) -> 30 | K25: =IFERROR(INDEX(Matching_Engine!$Z$6:$Z$95,MATCH($B25&"|"&$C25,Matching_Engine!$AZ$6:$AZ$95,0)),0) -> 30 | L25: =IFERROR(INDEX(Matching_Engine!$AB$6:$AB$95,MATCH($B25&"|"&$C25,Matching_Engine!$AZ$6:$AZ$95,0)),0) -> 30 | M25: =ROUND($H25*0.3+$I25*0.3+$J25*0.25+$L25*0.15,1) -> 40.2 | N25: =ROUND($G25*0.7+$M25*0.3,1) -> #VALUE! | O25: =IF($N25>=85,"Excellent Match",IF($N25>=70,"Strong Match",IF($N25>=55,"Good Match","Weak Match"))) -> #VALUE! | P25: ="Brand "&ROUND($G25,0)&"/100; Audience "&ROUND($H25,0)&"/100; Style "&ROUND($I25,0)&"/100; Personality "&ROUND($J25,0)&"/100. Campaign Fit "&ROUND($M25,0)&"/100." -> #VALUE!
A26: =Campaign_Profile!$B$5 -> CAMP-A | B26: =Campaign_Profile!$B$6 -> BRAND-A | C26: =KOL_Database!$A$26 -> KOL-22 | D26: =KOL_Database!$B$26 -> Nabila Kirana | E26: =KOL_Database!$D$26 -> Instagram | F26: =KOL_Database!$E$26 -> Entertainment | G26: =IFERROR(INDEX(Matching_Engine!$AY$6:$AY$95,MATCH($B26&"|"&$C26,Matching_Engine!$AZ$6:$AZ$95,0)),0) | H26: =IFERROR(INDEX(Matching_Engine!$S$6:$S$95,MATCH($B26&"|"&$C26,Matching_Engine!$AZ$6:$AZ$95,0)),0) -> 54 | I26: =IFERROR(INDEX(Matching_Engine!$W$6:$W$95,MATCH($B26&"|"&$C26,Matching_Engine!$AZ$6:$AZ$95,0)),0) -> 45 | J26: =IFERROR(INDEX(Matching_Engine!$Y$6:$Y$95,MATCH($B26&"|"&$C26,Matching_Engine!$AZ$6:$AZ$95,0)),0) -> 95 | K26: =IFERROR(INDEX(Matching_Engine!$Z$6:$Z$95,MATCH($B26&"|"&$C26,Matching_Engine!$AZ$6:$AZ$95,0)),0) -> 50 | L26: =IFERROR(INDEX(Matching_Engine!$AB$6:$AB$95,MATCH($B26&"|"&$C26,Matching_Engine!$AZ$6:$AZ$95,0)),0) -> 45 | M26: =ROUND($H26*0.3+$I26*0.3+$J26*0.25+$L26*0.15,1) -> 60.2 | N26: =ROUND($G26*0.7+$M26*0.3,1) -> #VALUE! | O26: =IF($N26>=85,"Excellent Match",IF($N26>=70,"Strong Match",IF($N26>=55,"Good Match","Weak Match"))) -> #VALUE! | P26: ="Brand "&ROUND($G26,0)&"/100; Audience "&ROUND($H26,0)&"/100; Style "&ROUND($I26,0)&"/100; Personality "&ROUND($J26,0)&"/100. Campaign Fit "&ROUND($M26,0)&"/100." -> #VALUE!
A27: =Campaign_Profile!$B$5 -> CAMP-A | B27: =Campaign_Profile!$B$6 -> BRAND-A | C27: =KOL_Database!$A$27 -> KOL-23 | D27: =KOL_Database!$B$27 -> Arya Mahendra | E27: =KOL_Database!$D$27 -> TikTok | F27: =KOL_Database!$E$27 -> Gaming | G27: =IFERROR(INDEX(Matching_Engine!$AY$6:$AY$95,MATCH($B27&"|"&$C27,Matching_Engine!$AZ$6:$AZ$95,0)),0) -> 57 | H27: =IFERROR(INDEX(Matching_Engine!$S$6:$S$95,MATCH($B27&"|"&$C27,Matching_Engine!$AZ$6:$AZ$95,0)),0) -> 57 | I27: =IFERROR(INDEX(Matching_Engine!$W$6:$W$95,MATCH($B27&"|"&$C27,Matching_Engine!$AZ$6:$AZ$95,0)),0) -> 45 | J27: =IFERROR(INDEX(Matching_Engine!$Y$6:$Y$95,MATCH($B27&"|"&$C27,Matching_Engine!$AZ$6:$AZ$95,0)),0) -> 45 | K27: =IFERROR(INDEX(Matching_Engine!$Z$6:$Z$95,MATCH($B27&"|"&$C27,Matching_Engine!$AZ$6:$AZ$95,0)),0) -> 40 | L27: =IFERROR(INDEX(Matching_Engine!$AB$6:$AB$95,MATCH($B27&"|"&$C27,Matching_Engine!$AZ$6:$AZ$95,0)),0) -> 40 | M27: =ROUND($H27*0.3+$I27*0.3+$J27*0.25+$L27*0.15,1) -> 47.9 | N27: =ROUND($G27*0.7+$M27*0.3,1) -> 54.3 | O27: =IF($N27>=85,"Excellent Match",IF($N27>=70,"Strong Match",IF($N27>=55,"Good Match","Weak Match"))) -> Weak Match | P27: ="Brand "&ROUND($G27,0)&"/100; Audience "&ROUND($H27,0)&"/100; Style "&ROUND($I27,0)&"/100; Personality "&ROUND($J27,0)&"/100. Campaign Fit "&ROUND($M27,0)&"/100." -> Brand 57/100; Audience 57/100; Style 45/100; Personality 45/100. Campaign Fit 48/100.
A28: =Campaign_Profile!$B$5 -> CAMP-A | B28: =Campaign_Profile!$B$6 -> BRAND-A | C28: =KOL_Database!$A$28 -> KOL-24 | D28: =KOL_Database!$B$28 -> Rio Saputra | E28: =KOL_Database!$D$28 -> Instagram | F28: =KOL_Database!$E$28 -> Gaming | G28: =IFERROR(INDEX(Matching_Engine!$AY$6:$AY$95,MATCH($B28&"|"&$C28,Matching_Engine!$AZ$6:$AZ$95,0)),0) -> 66 | H28: =IFERROR(INDEX(Matching_Engine!$S$6:$S$95,MATCH($B28&"|"&$C28,Matching_Engine!$AZ$6:$AZ$95,0)),0) -> 68 | I28: =IFERROR(INDEX(Matching_Engine!$W$6:$W$95,MATCH($B28&"|"&$C28,Matching_Engine!$AZ$6:$AZ$95,0)),0) -> 80 | J28: =IFERROR(INDEX(Matching_Engine!$Y$6:$Y$95,MATCH($B28&"|"&$C28,Matching_Engine!$AZ$6:$AZ$95,0)),0) -> 100 | K28: =IFERROR(INDEX(Matching_Engine!$Z$6:$Z$95,MATCH($B28&"|"&$C28,Matching_Engine!$AZ$6:$AZ$95,0)),0) -> 85 | L28: =IFERROR(INDEX(Matching_Engine!$AB$6:$AB$95,MATCH($B28&"|"&$C28,Matching_Engine!$AZ$6:$AZ$95,0)),0) -> 80 | M28: =ROUND($H28*0.3+$I28*0.3+$J28*0.25+$L28*0.15,1) -> 81.4 | N28: =ROUND($G28*0.7+$M28*0.3,1) -> 70.6 | O28: =IF($N28>=85,"Excellent Match",IF($N28>=70,"Strong Match",IF($N28>=55,"Good Match","Weak Match"))) -> Strong Match | P28: ="Brand "&ROUND($G28,0)&"/100; Audience "&ROUND($H28,0)&"/100; Style "&ROUND($I28,0)&"/100; Personality "&ROUND($J28,0)&"/100. Campaign Fit "&ROUND($M28,0)&"/100." -> Brand 66/100; Audience 68/100; Style 80/100; Personality 100/100. Campaign Fit 81/100.
A29: =Campaign_Profile!$B$5 -> CAMP-A | B29: =Campaign_Profile!$B$6 -> BRAND-A | C29: =KOL_Database!$A$29 -> KOL-25 | D29: =KOL_Database!$B$29 -> Denny Kurniawan | E29: =KOL_Database!$D$29 -> TikTok | F29: =KOL_Database!$E$29 -> Automotive | G29: =IFERROR(INDEX(Matching_Engine!$AY$6:$AY$95,MATCH($B29&"|"&$C29,Matching_Engine!$AZ$6:$AZ$95,0)),0) -> 54 | H29: =IFERROR(INDEX(Matching_Engine!$S$6:$S$95,MATCH($B29&"|"&$C29,Matching_Engine!$AZ$6:$AZ$95,0)),0) -> 57 | I29: =IFERROR(INDEX(Matching_Engine!$W$6:$W$95,MATCH($B29&"|"&$C29,Matching_Engine!$AZ$6:$AZ$95,0)),0) -> 45 | J29: =IFERROR(INDEX(Matching_Engine!$Y$6:$Y$95,MATCH($B29&"|"&$C29,Matching_Engine!$AZ$6:$AZ$95,0)),0) -> 40 | K29: =IFERROR(INDEX(Matching_Engine!$Z$6:$Z$95,MATCH($B29&"|"&$C29,Matching_Engine!$AZ$6:$AZ$95,0)),0) -> 55 | L29: =IFERROR(INDEX(Matching_Engine!$AB$6:$AB$95,MATCH($B29&"|"&$C29,Matching_Engine!$AZ$6:$AZ$95,0)),0) -> 50 | M29: =ROUND($H29*0.3+$I29*0.3+$J29*0.25+$L29*0.15,1) -> 48.1 | N29: =ROUND($G29*0.7+$M29*0.3,1) -> 52.2 | O29: =IF($N29>=85,"Excellent Match",IF($N29>=70,"Strong Match",IF($N29>=55,"Good Match","Weak Match"))) -> Weak Match | P29: ="Brand "&ROUND($G29,0)&"/100; Audience "&ROUND($H29,0)&"/100; Style "&ROUND($I29,0)&"/100; Personality "&ROUND($J29,0)&"/100. Campaign Fit "&ROUND($M29,0)&"/100." -> Brand 54/100; Audience 57/100; Style 45/100; Personality 40/100. Campaign Fit 48/100.
A30: =Campaign_Profile!$B$5 -> CAMP-A | B30: =Campaign_Profile!$B$6 -> BRAND-A | C30: =KOL_Database!$A$30 -> KOL-26 | D30: =KOL_Database!$B$30 -> Wisnu Adi | E30: =KOL_Database!$D$30 -> Instagram | F30: =KOL_Database!$E$30 -> Automotive | G30: =IFERROR(INDEX(Matching_Engine!$AY$6:$AY$95,MATCH($B30&"|"&$C30,Matching_Engine!$AZ$6:$AZ$95,0)),0) | H30: =IFERROR(INDEX(Matching_Engine!$S$6:$S$95,MATCH($B30&"|"&$C30,Matching_Engine!$AZ$6:$AZ$95,0)),0) -> 83 | I30: =IFERROR(INDEX(Matching_Engine!$W$6:$W$95,MATCH($B30&"|"&$C30,Matching_Engine!$AZ$6:$AZ$95,0)),0) -> 80 | J30: =IFERROR(INDEX(Matching_Engine!$Y$6:$Y$95,MATCH($B30&"|"&$C30,Matching_Engine!$AZ$6:$AZ$95,0)),0) -> 70 | K30: =IFERROR(INDEX(Matching_Engine!$Z$6:$Z$95,MATCH($B30&"|"&$C30,Matching_Engine!$AZ$6:$AZ$95,0)),0) -> 90 | L30: =IFERROR(INDEX(Matching_Engine!$AB$6:$AB$95,MATCH($B30&"|"&$C30,Matching_Engine!$AZ$6:$AZ$95,0)),0) -> 70 | M30: =ROUND($H30*0.3+$I30*0.3+$J30*0.25+$L30*0.15,1) -> 76.9 | N30: =ROUND($G30*0.7+$M30*0.3,1) -> #VALUE! | O30: =IF($N30>=85,"Excellent Match",IF($N30>=70,"Strong Match",IF($N30>=55,"Good Match","Weak Match"))) -> #VALUE! | P30: ="Brand "&ROUND($G30,0)&"/100; Audience "&ROUND($H30,0)&"/100; Style "&ROUND($I30,0)&"/100; Personality "&ROUND($J30,0)&"/100. Campaign Fit "&ROUND($M30,0)&"/100." -> #VALUE!
A31: =Campaign_Profile!$B$5 -> CAMP-A | B31: =Campaign_Profile!$B$6 -> BRAND-A | C31: =KOL_Database!$A$31 -> KOL-27 | D31: =KOL_Database!$B$31 -> Laras Ayu | E31: =KOL_Database!$D$31 -> Instagram | F31: =KOL_Database!$E$31 -> Home & Living | G31: =IFERROR(INDEX(Matching_Engine!$AY$6:$AY$95,MATCH($B31&"|"&$C31,Matching_Engine!$AZ$6:$AZ$95,0)),0) -> 42 | H31: =IFERROR(INDEX(Matching_Engine!$S$6:$S$95,MATCH($B31&"|"&$C31,Matching_Engine!$AZ$6:$AZ$95,0)),0) -> 49 | I31: =IFERROR(INDEX(Matching_Engine!$W$6:$W$95,MATCH($B31&"|"&$C31,Matching_Engine!$AZ$6:$AZ$95,0)),0) -> 45 | J31: =IFERROR(INDEX(Matching_Engine!$Y$6:$Y$95,MATCH($B31&"|"&$C31,Matching_Engine!$AZ$6:$AZ$95,0)),0) -> 60 | K31: =IFERROR(INDEX(Matching_Engine!$Z$6:$Z$95,MATCH($B31&"|"&$C31,Matching_Engine!$AZ$6:$AZ$95,0)),0) -> 50 | L31: =IFERROR(INDEX(Matching_Engine!$AB$6:$AB$95,MATCH($B31&"|"&$C31,Matching_Engine!$AZ$6:$AZ$95,0)),0) -> 45 | M31: =ROUND($H31*0.3+$I31*0.3+$J31*0.25+$L31*0.15,1) -> 50 | N31: =ROUND($G31*0.7+$M31*0.3,1) -> 44.4 | O31: =IF($N31>=85,"Excellent Match",IF($N31>=70,"Strong Match",IF($N31>=55,"Good Match","Weak Match"))) -> Weak Match | P31: ="Brand "&ROUND($G31,0)&"/100; Audience "&ROUND($H31,0)&"/100; Style "&ROUND($I31,0)&"/100; Personality "&ROUND($J31,0)&"/100. Campaign Fit "&ROUND($M31,0)&"/100." -> Brand 42/100; Audience 49/100; Style 45/100; Personality 60/100. Campaign Fit 50/100.
A32: =Campaign_Profile!$B$5 -> CAMP-A | B32: =Campaign_Profile!$B$6 -> BRAND-A | C32: =KOL_Database!$A$32 -> KOL-28 | D32: =KOL_Database!$B$32 -> Tiara Nisrina | E32: =KOL_Database!$D$32 -> TikTok | F32: =KOL_Database!$E$32 -> Home & Living | G32: =IFERROR(INDEX(Matching_Engine!$AY$6:$AY$95,MATCH($B32&"|"&$C32,Matching_Engine!$AZ$6:$AZ$95,0)),0) -> 55 | H32: =IFERROR(INDEX(Matching_Engine!$S$6:$S$95,MATCH($B32&"|"&$C32,Matching_Engine!$AZ$6:$AZ$95,0)),0) -> 66 | I32: =IFERROR(INDEX(Matching_Engine!$W$6:$W$95,MATCH($B32&"|"&$C32,Matching_Engine!$AZ$6:$AZ$95,0)),0) -> 80 | J32: =IFERROR(INDEX(Matching_Engine!$Y$6:$Y$95,MATCH($B32&"|"&$C32,Matching_Engine!$AZ$6:$AZ$95,0)),0) -> 50 | K32: =IFERROR(INDEX(Matching_Engine!$Z$6:$Z$95,MATCH($B32&"|"&$C32,Matching_Engine!$AZ$6:$AZ$95,0)),0) -> 95 | L32: =IFERROR(INDEX(Matching_Engine!$AB$6:$AB$95,MATCH($B32&"|"&$C32,Matching_Engine!$AZ$6:$AZ$95,0)),0) -> 95 | M32: =ROUND($H32*0.3+$I32*0.3+$J32*0.25+$L32*0.15,1) -> 70.6 | N32: =ROUND($G32*0.7+$M32*0.3,1) -> 59.7 | O32: =IF($N32>=85,"Excellent Match",IF($N32>=70,"Strong Match",IF($N32>=55,"Good Match","Weak Match"))) -> Good Match | P32: ="Brand "&ROUND($G32,0)&"/100; Audience "&ROUND($H32,0)&"/100; Style "&ROUND($I32,0)&"/100; Personality "&ROUND($J32,0)&"/100. Campaign Fit "&ROUND($M32,0)&"/100." -> Brand 55/100; Audience 66/100; Style 80/100; Personality 50/100. Campaign Fit 71/100.
